Workbook

Sheet Main
B1: {=_xlfn.SEQUENCE(,COUNTA(B2:V2))} -> 1 | C1: 2 | D1: 3 | E1: 4 | F1: 5 | G1: 6 | H1: 7 | I1: 8 | J1: 9 | K1: 10 | L1: 11 | M1: 12 | N1: 13 | O1: 14 | P1: 15 | Q1: 16 | R1: 17 | S1: 18 | T1: 19 | U1: 20
B2: CLIENTE | C2: DI /DSI DDE/DSE/DU-E | D2: N/REF | E2: S/REF | F2: AFRMM | G2: CE MERCANTE | H2: Alerta | I2: Prazo Contrato | J2: Contrato | K2: Descrição da Mercadoria | L2: PRAZO SOLICITADO | M2: Data de Registro | N2: Data de Desembaraço | O2: Unidade de Desembaraço | P2: CNPJ/MF PROCESSO | Q2: Processo Nacional | R2: DOSSIE | S2: PRAZO APOLICE (cobrar quando data estiver vermelha) | T2: Histórico | U2: MODAL
A3: =B3&" - "&COUNTIF($B$3:B3,B3) -> MAMMOET - 1 | B3: MAMMOET | C3: 2213721580 | D3: I-22/0968-MBG | F3: SUSPENSA | G3: 72205154296309 | H3: =EDATE(I3,-1) -> 45563 | I3: =EDATE(LEFT(L3,10),-1) -> 45593 | J3: CONTRATO DE LOCAÇÃO S/NR | K3: DISTRIBUIDOR DE CARGA METALICO, Fabricante Mammoet Lifting and Transport SAS, Modelo: HEB300- S235, ANO DE FABRICACAO: 2020, USADO,NUMERO DE EQUIPAMENTO: 200812-001; 200812-002; 200812-003; 200812-004; 200812-005; 200812-006; 200812-009; 200812-010. | L3: 28/11/2024 (REEXPORTADO) | M3: 44761 | N3: 44769 | O3: IRF - PORTO DE SUAPE | P3: 11426377000123 | R3: 202200158843967 | T3: 29/11/2024 - Reexportado através dos processos E-24/0382-MBG e E-24/0384-MBG 30/09/2024 - Cobrado procedimento a ser adotado 27/06/2024 - Juntada efetuada 27/06/2024 - Docs recebidos 17/06/2024 - Nuerario enviado, ag retorno 13/06/2024 - Prorrogação por mais 5 meses 03/06/2024 - Cobrado novamente 30/04/2024 - Cobrado procedimento a ser adotado 27/12/2023 - Juntada efetuada. 01/12/2023 - Enviado Numerario e RPR, ag retorno 22/11/2023 - Solicitado prorrogação por mais 6 meses 30/10/2023 - Cobrado procedimento a ser adotado 27/06/2023 - Juntada efetuada pelo DOSSIE 21/06/2023 - Documentação recebida 01/06/2023 - Cobrado novamente 03/05/2023 - Cobrado procedimento a ser adotado 22/09/2022 - Processo incluido no controle | U3: MARÍTIMO | V3: ="'"&SUBSTITUTE(T3,CHAR(10),"' + CHAR(13) + CHAR(10) + "&CHAR(10)&"'")&"'" -> '29/11/2024 - Reexportado através dos processos E-24/0382-MBG e E-24/0384-MBG' + CHAR(13) + CHAR(10) + '30/09/2024 - Cobrado procedimento a ser adotado' + CHAR(13) + CHAR(10) + '27/06/2024 - Juntada efetuada' + CHAR(13) + CHAR(10) + '27/06/2024 - Docs recebidos' + CHAR(13) + CHAR(10) + '17/06/2024 - Nuerario enviado, ag retorno' + CHAR(13) + CHAR(10) + '13/06/2024 - Prorrogação por mais 5 meses' + CHAR(13) + CHAR(10) + '03/06/2024 - Cobrado novamente' + CHAR(13) + CHAR(10) + '30/04/2024 - Cobrado procedimento a ser adotado' + CHAR(13) + CHAR(10) + '27/12/2023 - Juntada efetuada.' + CHAR(13) + CHAR(10) + '01/12/2023 - Enviado Numerario e RPR, ag retorno' + CHAR(13) + CHAR(10) + '22/11/2023 - Solicitado prorrogação por mais 6 meses' + CHAR(13) + CHAR(10) + '30/10/2023 - Cobrado procedimento a ser adotado' + CHAR(13) + CHAR(10) + '27/06/2023 - Juntada efetuada pelo DOSSIE' + CHAR(13) + CHAR(10) + '21/06/2023 - Documentação recebida' + CHAR(13) + CHAR(10) + '01/06/2023 - Cobrado novamente' + CHAR(13) + CHAR(10) + '03/05/2023 - Cobrado procedimento a ser adotado' + CHAR(13) + CHAR(10) + '22/09/2022 - Processo incluido no controle' | W3: {="WHEN "&_xlfn.SEQUENCE(COUNTA(B3:B56))&" THEN"&CHAR(10)&V3:V56} -> WHEN 1 THEN '29/11/2024 - Reexportado através dos processos E-24/0382-MBG e E-24/0384-MBG' + CHAR(13) + CHAR(10) + '30/09/2024 - Cobrado procedimento a ser adotado' + CHAR(13) + CHAR(10) + '27/06/2024 - Juntada efetuada' + CHAR(13) + CHAR(10) + '27/06/2024 - Docs recebidos' + CHAR(13) + CHAR(10) + '17/06/2024 - Nuerario enviado, ag retorno' + CHAR(13) + CHAR(10) + '13/06/2024 - Prorrogação por mais 5 meses' + CHAR(13) + CHAR(10) + '03/06/2024 - Cobrado novamente' + CHAR(13) + CHAR(10) + '30/04/2024 - Cobrado procedimento a ser adotado' + CHAR(13) + CHAR(10) + '27/12/2023 - Juntada efetuada.' + CHAR(13) + CHAR(10) + '01/12/2023 - Enviado Numerario e RPR, ag retorno' + CHAR(13) + CHAR(10) + '22/11/2023 - Solicitado prorrogação por mais 6 meses' + CHAR(13) + CHAR(10) + '30/10/2023 - Cobrado procedimento a ser adotado' + CHAR(13) + CHAR(10) + '27/06/2023 - Juntada efetuada pelo DOSSIE' + CHAR(13) + CHAR(10) + '21/06/2023 - Documentação recebida' + CHAR(13) + CHAR(10) + '01/06/2023 - Cobrado novamente' + CHAR(13) + CHAR(10) + '03/05/2023 - Cobrado procedimento a ser adotado' + CHAR(13) + CHAR(10) + '22/09/2022 - Processo incluido no controle' | X3: {="WHEN "&_xlfn.SEQUENCE(COUNTA(B3:B56))&" THEN"&CHAR(10)&"'"&UPPER(TRIM(K3:K56))&"'"} -> WHEN 1 THEN 'DISTRIBUIDOR DE CARGA METALICO, FABRICANTE MAMMOET LIFTING AND TRANSPORT SAS, MODELO: HEB300- S235, ANO DE FABRICACAO: 2020, USADO,NUMERO DE EQUIPAMENTO: 200812-001; 200812-002; 200812-003; 200812-004; 200812-005; 200812-006; 200812-009; 200812-010.'
A4: =B4&" - "&COUNTIF($B$3:B4,B4) -> MAMMOET - 2 | B4: MAMMOET | C4: 2406902926 | D4: I-24/0271-MBG | E4: CABOS E CONTRAPESO | F4: SUSPENSA | G4: 72405061514983 | H4: =EDATE(I4,-1) -> 45568 | I4: =EDATE(LEFT(L4,10),-1) -> 45599 | J4: CONTRATODE COMODATO DE 12/03/2024 | K4: CABOS DE AÇO, GALVANIZADO PARA GUINDASTE | L4: 03/12/2024 (REEXPORTADO) | M4: 45384 | N4: 45386 | O4: INST.PORT.USO PUBL.-SUATA SERV.LOG. LTDA. | P4: 11426377000123 | R4: 202400232144540 | T4: 29/11/2024 - Reexportado através dos processos E-24/0418-MBG 27/11/2024 - Cobrado novamente 01/11/2024 - Cobrado procedimento a ser adotado 29/10/2024 - Juntada efetuada 28/10/2024 - Docs recebidos 22/10/2024 - Numerario enviado, ag retorno 21/10/2024 - Solciitado prorrogaçao por mais 1 mes 14/10/2024 - Cobrado novamente 09/09/2024 - Cobrado procedimento a ser adotado 03/07/2024 - Juntada efetuada 02/07/2024 - Docs recebidos 25/06/2024 - Solicitado prorrogação por mais 4 meses, numerario enviado, ag retorno 10/06/2024 - Cobrado procedimento a ser adotado 03/06/2024 - Juntada efetuada 29/05/2024 - Docs recebidos 27/05/2024 - Enviado Numerario e RPR, ag retorno 21/05/2024 - Solicitado prorrogação por mais 1 mes 07/05/2024 - Cobrado procedimento a ser adotado 30/04/2024 - Processo incluído no controle | U4: MARÍTIMO | V4: ="'"&SUBSTITUTE(T4,CHAR(10),"' + CHAR(13) + CHAR(10) + "&CHAR(10)&"'")&"'" -> '29/11/2024 - Reexportado através dos processos E-24/0418-MBG' + CHAR(13) + CHAR(10) + '27/11/2024 - Cobrado novamente' + CHAR(13) + CHAR(10) + '01/11/2024 - Cobrado procedimento a ser adotado' + CHAR(13) + CHAR(10) + '29/10/2024 - Juntada efetuada' + CHAR(13) + CHAR(10) + '28/10/2024 - Docs recebidos' + CHAR(13) + CHAR(10) + '22/10/2024 - Numerario enviado, ag retorno' + CHAR(13) + CHAR(10) + '21/10/2024 - Solciitado prorrogaçao por mais 1 mes' + CHAR(13) + CHAR(10) + '14/10/2024 - Cobrado novamente' + CHAR(13) + CHAR(10) + '09/09/2024 - Cobrado procedimento a ser adotado' + CHAR(13) + CHAR(10) + '03/07/2024 - Juntada efetuada' + CHAR(13) + CHAR(10) + '02/07/2024 - Docs recebidos' + CHAR(13) + CHAR(10) + '25/06/2024 - Solicitado prorrogação por mais 4 meses, numerario enviado, ag retorno' + CHAR(13) + CHAR(10) + '10/06/2024 - Cobrado procedimento a ser adotado' + CHAR(13) + CHAR(10) + '03/06/2024 - Juntada efetuada' + CHAR(13) + CHAR(10) + '29/05/2024 - Docs recebidos' + CHAR(13) + CHAR(10) + '27/05/2024 - Enviado Numerario e RPR, ag retorno' + CHAR(13) + CHAR(10) + '21/05/2024 - Solicitado prorrogação por mais 1 mes' + CHAR(13) + CHAR(10) + '07/05/2024 - Cobrado procedimento a ser adotado' + CHAR(13) + CHAR(10) + '30/04/2024 - Processo incluído no controle' | W4: WHEN 2 THEN '29/11/2024 - Reexportado através dos processos E-24/0418-MBG' + CHAR(13) + CHAR(10) + '27/11/2024 - Cobrado novamente' + CHAR(13) + CHAR(10) + '01/11/2024 - Cobrado procedimento a ser adotado' + CHAR(13) + CHAR(10) + '29/10/2024 - Juntada efetuada' + CHAR(13) + CHAR(10) + '28/10/2024 - Docs recebidos' + CHAR(13) + CHAR(10) + '22/10/2024 - Numerario enviado, ag retorno' + CHAR(13) + CHAR(10) + '21/10/2024 - Solciitado prorrogaçao por mais 1 mes' + CHAR(13) + CHAR(10) + '14/10/2024 - Cobrado novamente' + CHAR(13) + CHAR(10) + '09/09/2024 - Cobrado procedimento a ser adotado' + CHAR(13) + CHAR(10) + '03/07/2024 - Juntada efetuada' + CHAR(13) + CHAR(10) + '02/07/2024 - Docs recebidos' + CHAR(13) + CHAR(10) + '25/06/2024 - Solicitado prorrogação por mais 4 meses, numerario enviado, ag retorno' + CHAR(13) + CHAR(10) + '10/06/2024 - Cobrado procedimento a ser adotado' + CHAR(13) + CHAR(10) + '03/06/2024 - Juntada efetuada' + CHAR(13) + CHAR(10) + '29/05/2024 - Docs recebidos' + CHAR(13) + CHAR(10) + '27/05/2024 - Enviado Numerario e RPR, ag retorno' + CHAR(13) + CHAR(10) + '21/05/2024 - Solicitado prorrogação por mais 1 mes' + CHAR(13) + CHAR(10) + '07/05/2024 - Cobrado procedimento a ser adotado' + CHAR(13) + CHAR(10) + '30/04/2024 - Processo incluído no controle' | X4: WHEN 2 THEN 'CABOS DE AÇO, GALVANIZADO PARA GUINDASTE'
A5: =B5&" - "&COUNTIF($B$3:B5,B5) -> MAMMOET - 3 | B5: MAMMOET | C5: 2215388101 | D5: I-22/1149-MBG | F5: SUSPENSA | G5: 72205156943263 | H5: =EDATE(I5,-1) -> 45577 | I5: =EDATE(LEFT(L5,10),-1) -> 45608 | J5: CONTRATO DE LOCAÇÃO S/NR | K5: DISTRIBUIDOR DE CARGA METALICO 3xHEB 500 Lg, Fabricante Servicios de Elevacion y Transporte- Mammoet Chile y Cia Ltda, Modelo:15104519-ENGDWG-F001-0, ANO DE FABRICACAO: 2022, USADO, NÚMERO DE EQUIPAMENTO: NA. | L5: 12/12/2024 (REEXPORTADO) | M5: 44783 | N5: 44785 | O5: IRF - PORTO DE SUAPE | P5: 11426377000123 | R5: 202200161707530 | T5: 29/11/2024 - Reexportado através do processo E-24/0406-MBG 27/11/2024 - Cobrado novamente 01/11/2024 - Cobrado procedimento a ser adotado 29/10/2024 - Juntada efetuada 28/10/2024 - Docs recebidos 22/10/2024 - Numerario enviado, ag retorno 21/10/2024 - Solciitado prorrogaçao por mais 1 mes 14/10/2024 - Cobrado novamente 30/09/2024 - Cobrado procedimento a ser adotado 13/06/2024 - Juntada efetuada 11/06/2024 - Docs recebidos 10/06/2024 - Numerario enviado, ag retorno 04/06/2024 - Prorrogação por mais 5 meses 03/06/2024 - Cobrado novamente 15/04/2024 - Cobrado procedimento a ser adotado 12/01/2024 - Juntada efetuada 12/01/2024 - Docs recebidos 04/01/2024 - Numerario e RPR enviados, agr retorno 03/01/2024 - Solicitado prorrogação por mais 4 meses 28/12/2023 - Cobrado novamente 21/11/2023 - Cobrado procedimento a ser adotado 10/07/2023 - Juntada efetuada através do DOSSIE 28/06/2023 - Docs recebidos 20/06/2023 - Numerario e TR enviado, ag retorno 19/06/2023 - Informado que será prorrogado por 6 meses 18/05/2023 - Cobrado procedimento a ser adotado 22/09/2022 - Processo incluido no controle | U5: MARÍTIMO | V5: ="'"&SUBSTITUTE(T5,CHAR(10),"' + CHAR(13) + CHAR(10) + "&CHAR(10)&"'")&"'" -> '29/11/2024 - Reexportado através do processo E-24/0406-MBG' + CHAR(13) + CHAR(10) + '27/11/2024 - Cobrado novamente' + CHAR(13) + CHAR(10) + '01/11/2024 - Cobrado procedimento a ser adotado' + CHAR(13) + CHAR(10) + '29/10/2024 - Juntada efetuada' + CHAR(13) + CHAR(10) + '28/10/2024 - Docs recebidos' + CHAR(13) + CHAR(10) + '22/10/2024 - Numerario enviado, ag retorno' + CHAR(13) + CHAR(10) + '21/10/2024 - Solciitado prorrogaçao por mais 1 mes' + CHAR(13) + CHAR(10) + '14/10/2024 - Cobrado novamente' + CHAR(13) + CHAR(10) + '30/09/2024 - Cobrado procedimento a ser adotado' + CHAR(13) + CHAR(10) + '13/06/2024 - Juntada efetuada' + CHAR(13) + CHAR(10) + '11/06/2024 - Docs recebidos' + CHAR(13) + CHAR(10) + '10/06/2024 - Numerario enviado, ag retorno' + CHAR(13) + CHAR(10) + '04/06/2024 - Prorrogação por mais 5 meses' + CHAR(13) + CHAR(10) + '03/06/2024 - Cobrado novamente' + CHAR(13) + CHAR(10) + '15/04/2024 - Cobrado procedimento a ser adotado' + CHAR(13) + CHAR(10) + '12/01/2024 - Juntada efetuada' + CHAR(13) + CHAR(10) + '12/01/2024 - Docs recebidos' + CHAR(13) + CHAR(10) + '04/01/2024 - Numerario e RPR enviados, agr retorno' + CHAR(13) + CHAR(10) + '03/01/2024 - Solicitado prorrogação por mais 4 meses' + CHAR(13) + CHAR(10) + '28/12/2023 - Cobrado novamente' + CHAR(13) + CHAR(10) + '21/11/2023 - Cobrado procedimento a ser adotado' + CHAR(13) + CHAR(10) + '10/07/2023 - Juntada efetuada através do DOSSIE' + CHAR(13) + CHAR(10) + '28/06/2023 - Docs recebidos' + CHAR(13) + CHAR(10) + '20/06/2023 - Numerario e TR enviado, ag retorno' + CHAR(13) + CHAR(10) + '19/06/2023 - Informado que será prorrogado por 6 meses' + CHAR(13) + CHAR(10) + '18/05/2023 - Cobrado procedimento a ser adotado' + CHAR(13) + CHAR(10) + '22/09/2022 - Processo incluido no controle' | W5: WHEN 3 THEN '29/11/2024 - Reexportado através do processo E-24/0406-MBG' + CHAR(13) + CHAR(10) + '27/11/2024 - Cobrado novamente' + CHAR(13) + CHAR(10) + '01/11/2024 - Cobrado procedimento a ser adotado' + CHAR(13) + CHAR(10) + '29/10/2024 - Juntada efetuada' + CHAR(13) + CHAR(10) + '28/10/2024 - Docs recebidos' + CHAR(13) + CHAR(10) + '22/10/2024 - Numerario enviado, ag retorno' + CHAR(13) + CHAR(10) + '21/10/2024 - Solciitado prorrogaçao por mais 1 mes' + CHAR(13) + CHAR(10) + '14/10/2024 - Cobrado novamente' + CHAR(13) + CHAR(10) + '30/09/2024 - Cobrado procedimento a ser adotado' + CHAR(13) + CHAR(10) + '13/06/2024 - Juntada efetuada' + CHAR(13) + CHAR(10) + '11/06/2024 - Docs recebidos' + CHAR(13) + CHAR(10) + '10/06/2024 - Numerario enviado, ag retorno' + CHAR(13) + CHAR(10) + '04/06/2024 - Prorrogação por mais 5 meses' + CHAR(13) + CHAR(10) + '03/06/2024 - Cobrado novamente' + CHAR(13) + CHAR(10) + '15/04/2024 - Cobrado procedimento a ser adotado' + CHAR(13) + CHAR(10) + '12/01/2024 - Juntada efetuada' + CHAR(13) + CHAR(10) + '12/01/2024 - Docs recebidos' + CHAR(13) + CHAR(10) + '04/01/2024 - Numerario e RPR enviados, agr retorno' + CHAR(13) + CHAR(10) + '03/01/2024 - Solicitado prorrogação por mais 4 meses' + CHAR(13) + CHAR(10) + '28/12/2023 - Cobrado novamente' + CHAR(13) + CHAR(10) + '21/11/2023 - Cobrado procedimento a ser adotado' + CHAR(13) + CHAR(10) + '10/07/2023 - Juntada efetuada através do DOSSIE' + CHAR(13) + CHAR(10) + '28/06/2023 - Docs recebidos' + CHAR(13) + CHAR(10) + '20/06/2023 - Numerario e TR enviado, ag retorno' + CHAR(13) + CHAR(10) + '19/06/2023 - Informado que será prorrogado por 6 meses' + CHAR(13) + CHAR(10) + '18/05/2023 - Cobrado procedimento a ser adotado' + CHAR(13) + CHAR(10) + '22/09/2022 - Processo incluido no controle' | X5: WHEN 3 THEN 'DISTRIBUIDOR DE CARGA METALICO 3XHEB 500 LG, FABRICANTE SERVICIOS DE ELEVACION Y TRANSPORTE- MAMMOET CHILE Y CIA LTDA, MODELO:15104519-ENGDWG-F001-0, ANO DE FABRICACAO: 2022, USADO, NÚMERO DE EQUIPAMENTO: NA.'
A6: =B6&" - "&COUNTIF($B$3:B6,B6) -> MAMMOET - 4 | B6: MAMMOET | C6: 2211469948 | D6: I-22/0680-MBG | E6: CC3800-1 | F6: SUSPENSA | G6: 102205138266757 | H6: =EDATE(I6,-1) -> 45585 | I6: =EDATE(LEFT(L6,10),-1) -> 45616 | J6: S/NR. | K6: Guindaste autopropelido sobre esteiras, novo, marca Terex-Demag, modelo CC 38.650-1, número de série 36254, ano de fabricação 2022, número da frota 003380, computadorizado, acionado por motor diesel, capacidade de 650 toneladas, superlift, contrapesos, com todos acessórios para seu funcionamento, desmontado parcialmente para manuseio e transporte. | L6: 20/12/2024 (REEXPORTADO) | M6: 44729 | N6: 44741 | O6: PORTO DE SALVADOR - CODEBA | P6: 11426377000123 | R6: 202200155225677 | T6: 29/11/2024 - Reexportado através dos processos E-24/0419-MBG 25/11/2024 - Cobrado procedimento a ser adotado 19/11/2024 - Juntada efetuada 13/11/2024 - Docs recebidos 11/11/2024 - Numerario enviado, ag retorno 07/11/2024 - Solcicitado prorrogaçao por mais 1 mes 30/09/2024 - Cobrado procedimento a ser adotado 20/06/2024 - Juntada efetuada 14/06/2024 - Docs recebidos 04/06/2024 - Prorrogação por mais 5 meses, ag retorno 03/06/2024 - Cobrado novamente 30/04/2024 - Cobrado procedimento a ser adotado 19/12/2023 - Juntada efetuada 01/12/2023 - Enviado RPR, TR e Numerario, ag retorno 22/11/2023 - Solicitado renovação por mais 6 meses 26/10/2023 - Cobrado procedimento a ser adotado 28/07/2022 - Processo incluido no controle | U6: MARÍTIMO | V6: ="'"&SUBSTITUTE(T6,CHAR(10),"' + CHAR(13) + CHAR(10) + "&CHAR(10)&"'")&"'" -> '29/11/2024 - Reexportado através dos processos E-24/0419-MBG' + CHAR(13) + CHAR(10) + '25/11/2024 - Cobrado procedimento a ser adotado' + CHAR(13) + CHAR(10) + '19/11/2024 - Juntada efetuada' + CHAR(13) + CHAR(10) + '13/11/2024 - Docs recebidos' + CHAR(13) + CHAR(10) + '11/11/2024 - Numerario enviado, ag retorno' + CHAR(13) + CHAR(10) + '07/11/2024 - Solcicitado prorrogaçao por mais 1 mes' + CHAR(13) + CHAR(10) + '30/09/2024 - Cobrado procedimento a ser adotado' + CHAR(13) + CHAR(10) + '20/06/2024 - Juntada efetuada' + CHAR(13) + CHAR(10) + '14/06/2024 - Docs recebidos' + CHAR(13) + CHAR(10) + '04/06/2024 - Prorrogação por mais 5 meses, ag retorno' + CHAR(13) + CHAR(10) + '03/06/2024 - Cobrado novamente' + CHAR(13) + CHAR(10) + '30/04/2024 - Cobrado procedimento a ser adotado' + CHAR(13) + CHAR(10) + '19/12/2023 - Juntada efetuada' + CHAR(13) + CHAR(10) + '01/12/2023 - Enviado RPR, TR e Numerario, ag retorno' + CHAR(13) + CHAR(10) + '22/11/2023 - Solicitado renovação por mais 6 meses' + CHAR(13) + CHAR(10) + '26/10/2023 - Cobrado procedimento a ser adotado' + CHAR(13) + CHAR(10) + '28/07/2022 - Processo incluido no controle' | W6: WHEN 4 THEN '29/11/2024 - Reexportado através dos processos E-24/0419-MBG' + CHAR(13) + CHAR(10) + '25/11/2024 - Cobrado procedimento a ser adotado' + CHAR(13) + CHAR(10) + '19/11/2024 - Juntada efetuada' + CHAR(13) + CHAR(10) + '13/11/2024 - Docs recebidos' + CHAR(13) + CHAR(10) + '11/11/2024 - Numerario enviado, ag retorno' + CHAR(13) + CHAR(10) + '07/11/2024 - Solcicitado prorrogaçao por mais 1 mes' + CHAR(13) + CHAR(10) + '30/09/2024 - Cobrado procedimento a ser adotado' + CHAR(13) + CHAR(10) + '20/06/2024 - Juntada efetuada' + CHAR(13) + CHAR(10) + '14/06/2024 - Docs recebidos' + CHAR(13) + CHAR(10) + '04/06/2024 - Prorrogação por mais 5 meses, ag retorno' + CHAR(13) + CHAR(10) + '03/06/2024 - Cobrado novamente' + CHAR(13) + CHAR(10) + '30/04/2024 - Cobrado procedimento a ser adotado' + CHAR(13) + CHAR(10) + '19/12/2023 - Juntada efetuada' + CHAR(13) + CHAR(10) + '01/12/2023 - Enviado RPR, TR e Numerario, ag retorno' + CHAR(13) + CHAR(10) + '22/11/2023 - Solicitado renovação por mais 6 meses' + CHAR(13) + CHAR(10) + '26/10/2023 - Cobrado procedimento a ser adotado' + CHAR(13) + CHAR(10) + '28/07/2022 - Processo incluido no controle' | X6: WHEN 4 THEN 'GUINDASTE AUTOPROPELIDO SOBRE ESTEIRAS, NOVO, MARCA TEREX-DEMAG, MODELO CC 38.650-1, NÚMERO DE SÉRIE 36254, ANO DE FABRICAÇÃO 2022, NÚMERO DA FROTA 003380, COMPUTADORIZADO, ACIONADO POR MOTOR DIESEL, CAPACIDADE DE 650 TONELADAS, SUPERLIFT, CONTRAPESOS, COM TODOS ACESSÓRIOS PARA SEU FUNCIONAMENTO, DESMONTADO PARCIALMENTE PARA MANUSEIO E TRANSPORTE.'
A7: =B7&" - "&COUNTIF($B$3:B7,B7) -> DTA ENGENHARIA - 1 | B7: DTA ENGENHARIA | C7: 2411169727 | D7: I-24/1100-DTE | E7: DRAGA FENFORD | H7: =EDATE(I7,-1) -> 45595 | I7: =EDATE(LEFT(L7,10),-1) -> 45626 | J7: PERIODO DE FORNECIMENTO 2017 CONTRATO DE AFRETAMENTO POR TEMPO PARA EMBARCAÇÕES DE APOIO OFFSHORE | K7: NOME DO NAVIO: KENFORD TIPO DE NAVIO: DRAGA DE SUCÇÃO TRANSPORTADORA DE ARRASTO. IMO: 8821826 BANDEIRA: BELIZE, CLASSE: DRAGA DE ARRASTO I HULL MACH, CLASSIFICAÇÃO: BUREAU VERITAS, DISTINTIVO DE CHAMADA V3BE2, CONSTRUÇÃO: 1990, PAÍSES BAIXOS. ESTÁ EQUIPADO COM SALA DE MÁQUINAS, COM SALA DE BOMBAS DE PROA, NO DEPÓSITO DE TINTA, COM SALA DE AR-CONDICIONADO, COM SALA DO LEME, COM TREMONHA E NA PONTE. O NAVIO ESTÁ EQUIPADO COM UMA ACOMODAÇÃO PARA 14 PESSOAS. DIMENSÕES: COMPRIMENTO TOTAL: 81,8M, COMPRIMENTO ENTRE PERPENDICULARES: 76,95M, LARGURA MOLDADA: 14,00M, PROFUNDIDADE MOLDADA NA MEIA-NAU: 6,30M, CALADO DE VERÃO:4,20M, CALADO DA DRAGA:5,25M, ALTURA:24M, TONELAGEM (T): TONELAGEM BRUTA:2172, TONELAGEM LÍQUIDA:664, PESO MORTO:3369 TONELADAS, CAPACIDADE DA TREMONHA (PARTE SUPERIOR DA ARMAÇÃO):2500 M3, TUBO DE SUCÇÃO DE TRILHAMENTO:1 COM DIÂMETRO DE 800 MM, TUBO DE DESCARGA PARA A TREMONHA: DIÂMETRO 800 MM, TUBO DE DESCARGA PARA TERRA: DIÂMETRO 650 MM, PROFUNDIDADE DE DRAGAGEM: 25M, VELOCIDADE MÁXIMA:10 NÓS, POTÊNCIA TOTAL INSTALADA DO MOTOR DIESEL: 1956 KW, MOTORES PRINCIPAIS:2 MOTORES A DIESEL BOLNES DE 7 CILINDROS, TIPO 7DNL 190/600, CADA UM COM POTÊNCIA NOMINAL DE 978 KW/1330 HP, A 600 RPM, CADA UM ACIONANDO 1 HÉLICE DE PASSO FIXO POR MEIO DE UMA CAIXA DE REDUÇÃO MASON. GERADOR AUXILIAR: 2 MOTOR DIESEL CATERPILLAR DE 4 CILINDROS, TIPO CAT 3304(B) DI-T, COM POTÊNCIA NOMINAL DE 80KW A 1.500 RPM, ACIONANDO 1 GERADOR. GERADOR DE EMERGÊNCIA: N/A, HÉLICES: 2 HÉLICES DE PASSO FIXO DE BRONZE COM 4 PÁS EM BOCAIS FIXOS. PROPULSOR DE PROA: 1 MOTOR PRINCIPAL BOLNES, GERADORES ACIONADOS (494KW) E HÉLICE DE PASSO FIXO NO TÚNEL. BOMBA DE DRAGAGEM: 1 BOMBA DE PAREDE SIMPLES VOSTA,TIPO IHC 150-42,5-75, ACIONADA POR UM MOTOR A DIESEL DE 978KW/1330HP, 600RPM, FABRICADO EM BOLNES POR MEIO DE UMA CAIXA DE REDUÇÃO TIPO CEGONHA. BOMBA DE REFORÇO: 1 BOMBA DE PAREDE SIMPLES VOSTA, TIPO IHC 175-37,5-75, ACIONADA POR UM MOTOR DIESEL DE 932 KW/1258 HP, 1800 RPM, CATERPILLAR 3512 DI-TA, POR MEIO DE UMA CAIXA DE REDUÇÃO (STORK). BOMBAS DE JATO DÁGUA: 2 BOMBAS GIW DE 1250M3/H, CADA UMA COM 8 BAR, ACIONADAS POR 1 MOTOR DIESEL CATERPILLAR 3412, MARCA HGT 1-300315-180KW. CAPACIDADE DO TANQUE: ÓLEO COMBUSTÍVEL: 269,0 M3 ÓLEOS LUBRIFICANTES 5,6 M3 ÁGUA DOCE: 55,7 T GUINDASTES DE CONVÉS: 1 GUINDASTE HIDRÁULICO PALFINGER, SWL,990 QUILOGRAMAS A 7M E 1 GUINDASTE ELÉTRICO, SWL, 990 QUILOGRAMAS A 6M.ACOMODAÇÃO: A ACOMODAÇÃO CONSISTE EM 3 BELICHES. APARELHOS SALVA-VIDAS:2 BOTES SALVA-VIDAS PARA 16 PESSOAS CADA, 2 BOTES SALVA VIDAS PARA 8 PESSOAS CADA, 1 BARCO MOB COM MOTOR DE POPA DE 25 HP, VÁRIOS OUTROS EQUIPAMENTOS. | L7: 31/12/2024 (REEXPORTADO) | M7: 45439 | N7: 45439 | O7: PATIO DO PORTO DO RJ | P7: 2385674000187 | R7: 202400238873528 | T7: 26/12/2024 - Reexportaçao através do processo E-24/0425-DTE 01/11/2024 - Cobrado procedimento a ser adotado 25/06/2024 - Processo incluído no controle | U7: MEIOS PRÓPRIOS | V7: ="'"&SUBSTITUTE(T7,CHAR(10),"' + CHAR(13) + CHAR(10) + "&CHAR(10)&"'")&"'" -> '26/12/2024 - Reexportaçao através do processo E-24/0425-DTE' + CHAR(13) + CHAR(10) + '01/11/2024 - Cobrado procedimento a ser adotado' + CHAR(13) + CHAR(10) + '25/06/2024 - Processo incluído no controle' | W7: WHEN 5 THEN '26/12/2024 - Reexportaçao através do processo E-24/0425-DTE' + CHAR(13) + CHAR(10) + '01/11/2024 - Cobrado procedimento a ser adotado' + CHAR(13) + CHAR(10) + '25/06/2024 - Processo incluído no controle' | X7: WHEN 5 THEN 'NOME DO NAVIO: KENFORD TIPO DE NAVIO: DRAGA DE SUCÇÃO TRANSPORTADORA DE ARRASTO. IMO: 8821826 BANDEIRA: BELIZE, CLASSE: DRAGA DE ARRASTO I HULL MACH, CLASSIFICAÇÃO: BUREAU VERITAS, DISTINTIVO DE CHAMADA V3BE2, CONSTRUÇÃO: 1990, PAÍSES BAIXOS. ESTÁ EQUIPADO COM SALA DE MÁQUINAS, COM SALA DE BOMBAS DE PROA, NO DEPÓSITO DE TINTA, COM SALA DE AR-CONDICIONADO, COM SALA DO LEME, COM TREMONHA E NA PONTE. O NAVIO ESTÁ EQUIPADO COM UMA ACOMODAÇÃO PARA 14 PESSOAS. DIMENSÕES: COMPRIMENTO TOTAL: 81,8M, COMPRIMENTO ENTRE PERPENDICULARES: 76,95M, LARGURA MOLDADA: 14,00M, PROFUNDIDADE MOLDADA NA MEIA-NAU: 6,30M, CALADO DE VERÃO:4,20M, CALADO DA DRAGA:5,25M, ALTURA:24M, TONELAGEM (T): TONELAGEM BRUTA:2172, TONELAGEM LÍQUIDA:664, PESO MORTO:3369 TONELADAS, CAPACIDADE DA TREMONHA (PARTE SUPERIOR DA ARMAÇÃO):2500 M3, TUBO DE SUCÇÃO DE TRILHAMENTO:1 COM DIÂMETRO DE 800 MM, TUBO DE DESCARGA PARA A TREMONHA: DIÂMETRO 800 MM, TUBO DE DESCARGA PARA TERRA: DIÂMETRO 650 MM, PROFUNDIDADE DE DRAGAGEM: 25M, VELOCIDADE MÁXIMA:10 NÓS, POTÊNCIA TOTAL INSTALADA DO MOTOR DIESEL: 1956 KW, MOTORES PRINCIPAIS:2 MOTORES A DIESEL BOLNES DE 7 CILINDROS, TIPO 7DNL 190/600, CADA UM COM POTÊNCIA NOMINAL DE 978 KW/1330 HP, A 600 RPM, CADA UM ACIONANDO 1 HÉLICE DE PASSO FIXO POR MEIO DE UMA CAIXA DE REDUÇÃO MASON. GERADOR AUXILIAR: 2 MOTOR DIESEL CATERPILLAR DE 4 CILINDROS, TIPO CAT 3304(B) DI-T, COM POTÊNCIA NOMINAL DE 80KW A 1.500 RPM, ACIONANDO 1 GERADOR. GERADOR DE EMERGÊNCIA: N/A, HÉLICES: 2 HÉLICES DE PASSO FIXO DE BRONZE COM 4 PÁS EM BOCAIS FIXOS. PROPULSOR DE PROA: 1 MOTOR PRINCIPAL BOLNES, GERADORES ACIONADOS (494KW) E HÉLICE DE PASSO FIXO NO TÚNEL. BOMBA DE DRAGAGEM: 1 BOMBA DE PAREDE SIMPLES VOSTA,TIPO IHC 150-42,5-75, ACIONADA POR UM MOTOR A DIESEL DE 978KW/1330HP, 600RPM, FABRICADO EM BOLNES POR MEIO DE UMA CAIXA DE REDUÇÃO TIPO CEGONHA. BOMBA DE REFORÇO: 1 BOMBA DE PAREDE SIMPLES VOSTA, TIPO IHC 175-37,5-75, ACIONADA POR UM MOTOR DIESEL DE 932 KW/1258 HP, 1800 RPM, CATERPILLAR 3512 DI-TA, POR MEIO DE UMA CAIXA DE REDUÇÃO (STORK). BOMBAS DE JATO DÁGUA: 2 BOMBAS GIW DE 1250M3/H, CADA UMA COM 8 BAR, ACIONADAS POR 1 MOTOR DIESEL CATERPILLAR 3412, MARCA HGT 1-300315-180KW. CAPACIDADE DO TANQUE: ÓLEO COMBUSTÍVEL: 269,0 M3 ÓLEOS LUBRIFICANTES 5,6 M3 ÁGUA DOCE: 55,7 T GUINDASTES DE CONVÉS: 1 GUINDASTE HIDRÁULICO PALFINGER, SWL,990 QUILOGRAMAS A 7M E 1 GUINDASTE ELÉTRICO, SWL, 990 QUILOGRAMAS A 6M.ACOMODAÇÃO: A ACOMODAÇÃO CONSISTE EM 3 BELICHES. APARELHOS SALVA-VIDAS:2 BOTES SALVA-VIDAS PARA 16 PESSOAS CADA, 2 BOTES SALVA VIDAS PARA 8 PESSOAS CADA, 1 BARCO MOB COM MOTOR DE POPA DE 25 HP, VÁRIOS OUTROS EQUIPAMENTOS.'
A8: =B8&" - "&COUNTIF($B$3:B8,B8) -> MAMMOET - 5 | B8: MAMMOET | C8: 2111602972 | D8: I-21/0721-MBG | E8: LTM1500-8.1 | F8: PAGA | G8: 72105117508099 | H8: =EDATE(I8,-1) -> 45617 | I8: =EDATE(LEFT(L8,10),-1) -> 45647 | J8: CONTRATO DE LOCAÇÃO 2021060 | K8: Caminhão Guindaste sobre Pneu com lança telescópica até 50 metros, aditivo especial conectado JIB até 91 metros, capacidade máxima de elevação 500 toneladas, com 8 eixos totais sendo 2 eixos fixos + 6 eixos direcionáveis, parcialmente desmontado para transporte e manuseio, com peças e acessórios para montagem e operação. Marca Liebherr, modelo LTM1500-8.1, usado, ano de fabricação 2017, numero de série 095381. | L8: 45678 | M8: 44364 | N8: 44368 | O8: SUATA SERV. LOG-SUAPE | P8: 11426377000123 | R8: 202100109389832 | S8: 46190 | T8: 26/12/2024 - Cobrado procedimento a ser adotado 20/12/2024 - Juntada efetuada 19/12/2024 - Docs recebidos 25/11/2024 - Cobrado procedimento a ser adotado 21/11/2024 - Juntada efetuada 19/11/2024 - Docs recebidos 14/11/2024 - Numerario enviado, ag retorno 12/11/2024 - Solicitado prorrogação por mais 1 mes 30/09/2024 - Cobrado procedimento a ser adotado 21/08/2024 - Juntada efetuada 21/08/2024 - Docs recebidos 07/08/2024 - Numerario enviado, ag numerario 05/08/2024 - Solicitado prorrogação por mais 3 meses 25/07/2024 - Cobrado novamente 25/06/2024 - Cobrado procedimento a ser adotado 21/06/2024 - Juntada efetuada 19/06/2024 - Docs recebidos 10/06/2024 - Enviado Numerario, ag retorno 04/06/2024 -Solicitado prorrogação por mais 2 meses 03/06/2024 - Cobrado novamente 30/04/2024 - Cobrado procedimento a ser adotado 19/04/2024 - Juntada efetuada 12/04/2024 - Dcos recebidos 05/04/2024 - Numerario e TR enviados 04/04/2024 - Informado que será prorrogado por mais 2 meses 22/03/2024 - Cobrado novamente 23/02/2024 - Cobrado procedimento a ser adotado 18/09/2023 - Juntada efetuada pelo DOSSIE 04/09/2023 - Docs recebidos 27/07/2023 - Cobrado procedimento a ser adotado 21/07/2023 - Juntada da Apolice efetuada 20/07/2023 - Juntada efetuada sem Apolice, através do DOSSIE 18/07/2023 - Recebido docs, exceto Apolice 27/06/2023 - Numerario, TR e RPR enviados, ag retorno 21/06/2023 - Informado que será prorrogado por 2 meses 01/06/2023 - Cobrado procedimento a ser adotado 22/03/2023 - Recebido Apolice, juntado ao DOSSIE 21/03/2023 - Juntada efetuada, ag Apolice 21/03/2023 - Docs recebidos exceto Apolice. 01/02/2023 - Enviado Numerario, RPR e TR, aguardando retorno 26/01/2023 - Informado que a prorrogação será até 08/2023 24/01/2023 - Cobrado procedimento a ser adotado 20/12/2022 - Juntada efetuada no DOSSIE 19/12/2022 - Docs recebidos 22/11/2022 - Cobrado novamente 25/10/2022 - Cobrado procedimento a ser adotado 25/06/2021 - Processo incluido no controle | U8: MARÍTIMO | V8: ="'"&SUBSTITUTE(T8,CHAR(10),"' + CHAR(13) + CHAR(10) + "&CHAR(10)&"'")&"'" -> '26/12/2024 - Cobrado procedimento a ser adotado' + CHAR(13) + CHAR(10) + '20/12/2024 - Juntada efetuada' + CHAR(13) + CHAR(10) + '19/12/2024 - Docs recebidos' + CHAR(13) + CHAR(10) + '25/11/2024 - Cobrado procedimento a ser adotado' + CHAR(13) + CHAR(10) + '21/11/2024 - Juntada efetuada' + CHAR(13) + CHAR(10) + '19/11/2024 - Docs recebidos' + CHAR(13) + CHAR(10) + '14/11/2024 - Numerario enviado, ag retorno' + CHAR(13) + CHAR(10) + '12/11/2024 - Solicitado prorrogação por mais 1 mes' + CHAR(13) + CHAR(10) + '30/09/2024 - Cobrado procedimento a ser adotado' + CHAR(13) + CHAR(10) + '21/08/2024 - Juntada efetuada' + CHAR(13) + CHAR(10) + '21/08/2024 - Docs recebidos' + CHAR(13) + CHAR(10) + '07/08/2024 - Numerario enviado, ag numerario' + CHAR(13) + CHAR(10) + '05/08/2024 - Solicitado prorrogação por mais 3 meses' + CHAR(13) + CHAR(10) + '25/07/2024 - Cobrado novamente' + CHAR(13) + CHAR(10) + '25/06/2024 - Cobrado procedimento a ser adotado' + CHAR(13) + CHAR(10) + '21/06/2024 - Juntada efetuada' + CHAR(13) + CHAR(10) + '19/06/2024 - Docs recebidos' + CHAR(13) + CHAR(10) + '10/06/2024 - Enviado Numerario, ag retorno' + CHAR(13) + CHAR(10) + '04/06/2024 -Solicitado prorrogação por mais 2 meses' + CHAR(13) + CHAR(10) + '03/06/2024 - Cobrado novamente' + CHAR(13) + CHAR(10) + '30/04/2024 - Cobrado procedimento a ser adotado' + CHAR(13) + CHAR(10) + '19/04/2024 - Juntada efetuada' + CHAR(13) + CHAR(10) + '12/04/2024 - Dcos recebidos' + CHAR(13) + CHAR(10) + '05/04/2024 - Numerario e TR enviados' + CHAR(13) + CHAR(10) + '04/04/2024 - Informado que será prorrogado por mais 2 meses' + CHAR(13) + CHAR(10) + '22/03/2024 - Cobrado novamente' + CHAR(13) + CHAR(10) + '23/02/2024 - Cobrado procedimento a ser adotado' + CHAR(13) + CHAR(10) + '18/09/2023 - Juntada efetuada pelo DOSSIE' + CHAR(13) + CHAR(10) + '04/09/2023 - Docs recebidos' + CHAR(13) + CHAR(10) + '27/07/2023 - Cobrado procedimento a ser adotado' + CHAR(13) + CHAR(10) + '21/07/2023 - Juntada da Apolice efetuada' + CHAR(13) + CHAR(10) + '20/07/2023 - Juntada efetuada sem Apolice, através do DOSSIE' + CHAR(13) + CHAR(10) + '18/07/2023 - Recebido docs, exceto Apolice' + CHAR(13) + CHAR(10) + '27/06/2023 - Numerario, TR e RPR enviados, ag retorno' + CHAR(13) + CHAR(10) + '21/06/2023 - Informado que será prorrogado por 2 meses' + CHAR(13) + CHAR(10) + '01/06/2023 - Cobrado procedimento a ser adotado' + CHAR(13) + CHAR(10) + '22/03/2023 - Recebido Apolice, juntado ao DOSSIE' + CHAR(13) + CHAR(10) + '21/03/2023 - Juntada efetuada, ag Apolice' + CHAR(13) + CHAR(10) + '21/03/2023 - Docs recebidos exceto Apolice.' + CHAR(13) + CHAR(10) + '01/02/2023 - Enviado Numerario, RPR e TR, aguardando retorno' + CHAR(13) + CHAR(10) + '26/01/2023 - Informado que a prorrogação será até 08/2023' + CHAR(13) + CHAR(10) + '24/01/2023 - Cobrado procedimento a ser adotado' + CHAR(13) + CHAR(10) + '20/12/2022 - Juntada efetuada no DOSSIE' + CHAR(13) + CHAR(10) + '19/12/2022 - Docs recebidos' + CHAR(13) + CHAR(10) + '22/11/2022 - Cobrado novamente' + CHAR(13) + CHAR(10) + '25/10/2022 - Cobrado procedimento a ser adotado' + CHAR(13) + CHAR(10) + '25/06/2021 - Processo incluido no controle' | W8: WHEN 6 THEN '26/12/2024 - Cobrado procedimento a ser adotado' + CHAR(13) + CHAR(10) + '20/12/2024 - Juntada efetuada' + CHAR(13) + CHAR(10) + '19/12/2024 - Docs recebidos' + CHAR(13) + CHAR(10) + '25/11/2024 - Cobrado procedimento a ser adotado' + CHAR(13) + CHAR(10) + '21/11/2024 - Juntada efetuada' + CHAR(13) + CHAR(10) + '19/11/2024 - Docs recebidos' + CHAR(13) + CHAR(10) + '14/11/2024 - Numerario enviado, ag retorno' + CHAR(13) + CHAR(10) + '12/11/2024 - Solicitado prorrogação por mais 1 mes' + CHAR(13) + CHAR(10) + '30/09/2024 - Cobrado procedimento a ser adotado' + CHAR(13) + CHAR(10) + '21/08/2024 - Juntada efetuada' + CHAR(13) + CHAR(10) + '21/08/2024 - Docs recebidos' + CHAR(13) + CHAR(10) + '07/08/2024 - Numerario enviado, ag numerario' + CHAR(13) + CHAR(10) + '05/08/2024 - Solicitado prorrogação por mais 3 meses' + CHAR(13) + CHAR(10) + '25/07/2024 - Cobrado novamente' + CHAR(13) + CHAR(10) + '25/06/2024 - Cobrado procedimento a ser adotado' + CHAR(13) + CHAR(10) + '21/06/2024 - Juntada efetuada' + CHAR(13) + CHAR(10) + '19/06/2024 - Docs recebidos' + CHAR(13) + CHAR(10) + '10/06/2024 - Enviado Numerario, ag retorno' + CHAR(13) + CHAR(10) + '04/06/2024 -Solicitado prorrogação por mais 2 meses' + CHAR(13) + CHAR(10) + '03/06/2024 - Cobrado novamente' + CHAR(13) + CHAR(10) + '30/04/2024 - Cobrado procedimento a ser adotado' + CHAR(13) + CHAR(10) + '19/04/2024 - Juntada efetuada' + CHAR(13) + CHAR(10) + '12/04/2024 - Dcos recebidos' + CHAR(13) + CHAR(10) + '05/04/2024 - Numerario e TR enviados' + CHAR(13) + CHAR(10) + '04/04/2024 - Informado que será prorrogado por mais 2 meses' + CHAR(13) + CHAR(10) + '22/03/2024 - Cobrado novamente' + CHAR(13) + CHAR(10) + '23/02/2024 - Cobrado procedimento a ser adotado' + CHAR(13) + CHAR(10) + '18/09/2023 - Juntada efetuada pelo DOSSIE' + CHAR(13) + CHAR(10) + '04/09/2023 - Docs recebidos' + CHAR(13) + CHAR(10) + '27/07/2023 - Cobrado procedimento a ser adotado' + CHAR(13) + CHAR(10) + '21/07/2023 - Juntada da Apolice efetuada' + CHAR(13) + CHAR(10) + '20/07/2023 - Juntada efetuada sem Apolice, através do DOSSIE' + CHAR(13) + CHAR(10) + '18/07/2023 - Recebido docs, exceto Apolice' + CHAR(13) + CHAR(10) + '27/06/2023 - Numerario, TR e RPR enviados, ag retorno' + CHAR(13) + CHAR(10) + '21/06/2023 - Informado que será prorrogado por 2 meses' + CHAR(13) + CHAR(10) + '01/06/2023 - Cobrado procedimento a ser adotado' + CHAR(13) + CHAR(10) + '22/03/2023 - Recebido Apolice, juntado ao DOSSIE' + CHAR(13) + CHAR(10) + '21/03/2023 - Juntada efetuada, ag Apolice' + CHAR(13) + CHAR(10) + '21/03/2023 - Docs recebidos exceto Apolice.' + CHAR(13) + CHAR(10) + '01/02/2023 - Enviado Numerario, RPR e TR, aguardando retorno' + CHAR(13) + CHAR(10) + '26/01/2023 - Informado que a prorrogação será até 08/2023' + CHAR(13) + CHAR(10) + '24/01/2023 - Cobrado procedimento a ser adotado' + CHAR(13) + CHAR(10) + '20/12/2022 - Juntada efetuada no DOSSIE' + CHAR(13) + CHAR(10) + '19/12/2022 - Docs recebidos' + CHAR(13) + CHAR(10) + '22/11/2022 - Cobrado novamente' + CHAR(13) + CHAR(10) + '25/10/2022 - Cobrado procedimento a ser adotado' + CHAR(13) + CHAR(10) + '25/06/2021 - Processo incluido no controle' | X8: WHEN 6 THEN 'CAMINHÃO GUINDASTE SOBRE PNEU COM LANÇA TELESCÓPICA ATÉ 50 METROS, ADITIVO ESPECIAL CONECTADO JIB ATÉ 91 METROS, CAPACIDADE MÁXIMA DE ELEVAÇÃO 500 TONELADAS, COM 8 EIXOS TOTAIS SENDO 2 EIXOS FIXOS + 6 EIXOS DIRECIONÁVEIS, PARCIALMENTE DESMONTADO PARA TRANSPORTE E MANUSEIO, COM PEÇAS E ACESSÓRIOS PARA MONTAGEM E OPERAÇÃO. MARCA LIEBHERR, MODELO LTM1500-8.1, USADO, ANO DE FABRICAÇÃO 2017, NUMERO DE SÉRIE 095381.'
A9: =B9&" - "&COUNTIF($B$3:B9,B9) -> KARINA - 1 | B9: KARINA | C9: 240010523748 | D9: E-24/0208-KRN | E9: EXP TEMPORARIA | H9: =EDATE(I9,-1) -> 45618 | I9: =EDATE(LEFT(L9,10),-1) -> 45648 | J9: CRONOGRAMA DE 20/06/2024 | K9: UNIDADE DE ACIONAMENTO EXTRUSORA E20 3F/1,1KW/I=16, DE MATERIAL EM AÇO, MODELO: M332.00256, NUMERO DE SERIE: 2021.3888.010.004, FABRICANTE: COLLIN LAB & PILOT SOLUTIONS GMBH | L9: 45679 | M9: 45467 | N9: 45468 | O9: AEROPORTO INTERNACIONAL DE SAO PAULO/GUARULHOS | P9: 51254159000173 | R9: 202400242169252 | T9: 26/12/2024 - Cobrado procedimento a ser adotado 18/12/2024 - Juntada efetuada 18/12/2024 - Docs recebidos 27/11/2024 - Informado que será reimportado 27/11/2024 - Cobrado novamente 28/10/2024 - Cobrado procedimento a ser adotado 23/10/2024 - Juntada efetuada 23/10/2024 - Docs recebidos 09/09/2024 - Cobrado procedimento a ser adotado 11/07/2024 - Processo incluído no controle | U9: AÉREO | V9: ="'"&SUBSTITUTE(T9,CHAR(10),"' + CHAR(13) + CHAR(10) + "&CHAR(10)&"'")&"'" -> '26/12/2024 - Cobrado procedimento a ser adotado' + CHAR(13) + CHAR(10) + '18/12/2024 - Juntada efetuada' + CHAR(13) + CHAR(10) + '18/12/2024 - Docs recebidos' + CHAR(13) + CHAR(10) + '27/11/2024 - Informado que será reimportado' + CHAR(13) + CHAR(10) + '27/11/2024 - Cobrado novamente' + CHAR(13) + CHAR(10) + '28/10/2024 - Cobrado procedimento a ser adotado' + CHAR(13) + CHAR(10) + '23/10/2024 - Juntada efetuada' + CHAR(13) + CHAR(10) + '23/10/2024 - Docs recebidos' + CHAR(13) + CHAR(10) + '09/09/2024 - Cobrado procedimento a ser adotado' + CHAR(13) + CHAR(10) + '11/07/2024 - Processo incluído no controle' | W9: WHEN 7 THEN '26/12/2024 - Cobrado procedimento a ser adotado' + CHAR(13) + CHAR(10) + '18/12/2024 - Juntada efetuada' + CHAR(13) + CHAR(10) + '18/12/2024 - Docs recebidos' + CHAR(13) + CHAR(10) + '27/11/2024 - Informado que será reimportado' + CHAR(13) + CHAR(10) + '27/11/2024 - Cobrado novamente' + CHAR(13) + CHAR(10) + '28/10/2024 - Cobrado procedimento a ser adotado' + CHAR(13) + CHAR(10) + '23/10/2024 - Juntada efetuada' + CHAR(13) + CHAR(10) + '23/10/2024 - Docs recebidos' + CHAR(13) + CHAR(10) + '09/09/2024 - Cobrado procedimento a ser adotado' + CHAR(13) + CHAR(10) + '11/07/2024 - Processo incluído no controle' | X9: WHEN 7 THEN 'UNIDADE DE ACIONAMENTO EXTRUSORA E20 3F/1,1KW/I=16, DE MATERIAL EM AÇO, MODELO: M332.00256, NUMERO DE SERIE: 2021.3888.010.004, FABRICANTE: COLLIN LAB & PILOT SOLUTIONS GMBH'
A10: =B10&" - "&COUNTIF($B$3:B10,B10) -> MEGASIL - 1 | B10: MEGASIL | C10: 2102189170 | D10: I-20/1533-MEG | E10: FORRAGEIRA+PLATAFORMA | F10: PAGA | G10: 152005271192929 | H10: =EDATE(I10,-1) -> 45630 | I10: =EDATE(LEFT(L10,10),-1) -> 45661 | J10: CONTRATO DE LOCAÇÃO Nº DH-MEGA17 | K10: DIVERSOS EQUIPAMENTOS CONFORME DI | L10: 45692 | M10: 44230 | N10: 44231 | O10: EADI AURORA - SOROCABA | P10: 2295964000130 | R10: 202100097363944 | T10: 26/12/2024 - Cobrado procedimento a ser adotado 23/03/2021 - Processo incluido no controle | U10: MARÍTIMO | V10: ="'"&SUBSTITUTE(T10,CHAR(10),"' + CHAR(13) + CHAR(10) + "&CHAR(10)&"'")&"'" -> '26/12/2024 - Cobrado procedimento a ser adotado' + CHAR(13) + CHAR(10) + '23/03/2021 - Processo incluido no controle' | W10: WHEN 8 THEN '26/12/2024 - Cobrado procedimento a ser adotado' + CHAR(13) + CHAR(10) + '23/03/2021 - Processo incluido no controle' | X10: WHEN 8 THEN 'DIVERSOS EQUIPAMENTOS CONFORME DI'
A11: =B11&" - "&COUNTIF($B$3:B11,B11) -> DTA ENGENHARIA - 2 | B11: DTA ENGENHARIA | C11: 2412607809 | D11: I-24/1261-DTE | E11: DRAGA ELBE | H11: =EDATE(I11,-1) -> 45644 | I11: =EDATE(LEFT(L11,10),-1) -> 45675 | J11: CONTRATO Nº 01 DE AFRETAMENTO DE DRAGA A CASCO NU | K11: DRAGA TSHD DE SUCÇÃO EM MOVIMENTO, M/V ELBE, CONSTRUÍDA EM 2007 NO ESTALEIRO BEN KIEN SHIPYARD, VIETNAM, REGISTRADA NO PORTO DE SLIEDRECH, DE BANDEIRA DOS PAISES BAIXOS, IMO NUMERO 9452842, INDICATIVO PBMK, A EMBARCAÇÃO ESTÁ EQUIPADO COM UM SISTEMA DE SUCÇÃO DE REBOQUE, DESPEJO E DESCARGA DE AREIA E LODO. ESTÁ EQUIPADA DE SALA DE MÁQUINAS, SALA DE BOMBA, LOJA DE TINTAS, QUARTO COM AR CONDICIONADO, SALA DE LEME, SALA DE HIDRÁULICA, 2 HOPPER (1 A BOMBORDO E 1 A ESTIBORDO), SALA DE CONVERSOR, SALA DE GERADOR, DE EMERGÊNCIA E PONTE. O NAVIO É EQUIPADO COM UM ALOJAMENTO PARA 13 PESSOAS. DRAGA AVALIADA EM 5.000.000,00 DIMENSÕES: COMPRIMENTO SOBRE TUDO: 77,15 M COMPRIMENTO PERPENDICULARES: 71,80 M BOCA MOLDADA: 15,00 M PROFUNDIDADE MEIA NAU MOLDADO: 5,70 M PROJECTO DE VERÃO: 4,45 M DRAGA PROJECTO: 6,10 M ALTURA: 28,85 M TONELAGEM (T): TONELAGEM BRUTA: 2472 TONELAGEM LIQUIDA: 741 PESO MORTO: 3341 MT CAPACIDADE HOPPER (TOPO DA BRAÇOLA): 2.800 M3 TUBO DE SUCÇÃO EM MOVIMENTO: 1 COM 800 MILÍMETROS DE DIÂMETRO TUBO DE DESCARGA PARA HOPER: 800 MILÍMETROS DE DIÂMETRO TUBO DE DESCARGA PARA TERRA: 600 MILÍMETROS DE DIÂMETRO PROFUNDIDADE DE DRAGAGEM: 30M VELOCIDADE MÁXIMA: 10,3 NÓS TOTAL DE ENERGIA A DIESEL INSTALADOS: 2.529 KW MOTORES PRICIPAIS: 2 MOTORES DIESEL DE 12 CILINDROS, MITSUBISHI, TIPO S12RMPTK, CADA UM DE 940 KW NOMINAL DE 1,600 RPM, DIRIGINDO UMA HÉLICE DE PASSO FIXO ATRAVÉS DE UMA CAIXA REDUTORA MASON. MOTORES AUXILIARES: 3 MOTORES DIESEL DE 6 CILINDROS, JOHN DEERE, TIPO 6090AFM85, DE 192KW NOMINAL DE 1,500 RPM, DE UNICA DIREÇÃO. MOTOR DE EMERGÊNCIA: 1 MOTOR DIESEL DE 6 CILINDROS, MITSUBISHI,TIPO 6D16T DE 106 KW NOMINAL DE 1500 RPM, DE UNICA DIREÇÃO. HÉLICES: 2 HÉLICES DE 5 PÁS DE BRONZE DE PASSO E BICOS FIXOS. MOTOR PROA: 1 MOTOR DIESEL, MITSUBSHI, HÉLICE DE PASSO FIXO CONDUZIDO EM TÚNEL DE 360KW. BOMBA DE DRAGAGEM: 1 BOMBA PARA DRAGAGEM VOSTA, TIPO VL 750, IMPULSIONADA POR UM MOTOR A DIESEL DE 870 KW MITSUBISHI, VIA CAIXA DE REDUÇÃO STORK. BOMBA DE MOVIMENTO: 1 BOMBA DE MOVIMENTO VOSTA, TIPO VL 750, IMPULSIONADA POR UM MOTOR A DIESEL DE 870 KW MITSUBISHI, VIA CAIXA DE REDUÇÃO STORK. BOMBAS DE JATO DE ÁGUA: 1 BOMBA GIW DE 2300 M3/H, DE 8 BAR, IMPULSIONADA POR UM MOTOR DIESEL, MITSHUBISHI DE 634 KW, COM REDUÇÃO VIA CAIXA MASON. CAPACIDADE DOS TANQUES DE: ÓLEO COMBUSTÍVEL: 219,0 M3 ÓLEOS LUBRIFICANTES: 13,0 M3 ÁGUA DOCE: 91,0 M3 GUINDASTES: 2 GRUAS HIDRÁULICAS PALFINGER, TIPO SWM, DE 7 TON ATÉ 10M. ACOMODAÇÕES: AS ACOMODAÇÕES CONSISTEM DE 5 DECKS. MEIOS DE SALVAÇÃO: 2 BOTES SALVA-VIDAS PARA CADA 16 PESSOAS, 1 BARCO MOB COM MOTOR DE POPA DE 25 HP. | L11: 45706 | M11: 45457 | N11: 45461 | O11: PORTO DE FORTALEZA - DOCAS DO CEARA | P11: 2385674000187 | R11: 202400241046459 | T11: 26/12/2024 - Cobrado procedimento a ser adotado 14/10/2024 - Juntada efetuada 14/10/2024 - Docs recebidos 07/10/2024 - Solicitado prorrogaçao por mais 3 meses, numerario e RPR enviados, ag retorno 14/08/2024 - Cobrado procedimento a ser adotado 22/07/2024 - Processo incluído no controle | U11: MEIOS PRÓPRIOS | V11: ="'"&SUBSTITUTE(T11,CHAR(10),"' + CHAR(13) + CHAR(10) + "&CHAR(10)&"'")&"'" -> '26/12/2024 - Cobrado procedimento a ser adotado' + CHAR(13) + CHAR(10) + '14/10/2024 - Juntada efetuada' + CHAR(13) + CHAR(10) + '14/10/2024 - Docs recebidos' + CHAR(13) + CHAR(10) + '07/10/2024 - Solicitado prorrogaçao por mais 3 meses, numerario e RPR enviados, ag retorno' + CHAR(13) + CHAR(10) + '14/08/2024 - Cobrado procedimento a ser adotado' + CHAR(13) + CHAR(10) + '22/07/2024 - Processo incluído no controle' | W11: WHEN 9 THEN '26/12/2024 - Cobrado procedimento a ser adotado' + CHAR(13) + CHAR(10) + '14/10/2024 - Juntada efetuada' + CHAR(13) + CHAR(10) + '14/10/2024 - Docs recebidos' + CHAR(13) + CHAR(10) + '07/10/2024 - Solicitado prorrogaçao por mais 3 meses, numerario e RPR enviados, ag retorno' + CHAR(13) + CHAR(10) + '14/08/2024 - Cobrado procedimento a ser adotado' + CHAR(13) + CHAR(10) + '22/07/2024 - Processo incluído no controle' | X11: WHEN 9 THEN 'DRAGA TSHD DE SUCÇÃO EM MOVIMENTO, M/V ELBE, CONSTRUÍDA EM 2007 NO ESTALEIRO BEN KIEN SHIPYARD, VIETNAM, REGISTRADA NO PORTO DE SLIEDRECH, DE BANDEIRA DOS PAISES BAIXOS, IMO NUMERO 9452842, INDICATIVO PBMK, A EMBARCAÇÃO ESTÁ EQUIPADO COM UM SISTEMA DE SUCÇÃO DE REBOQUE, DESPEJO E DESCARGA DE AREIA E LODO. ESTÁ EQUIPADA DE SALA DE MÁQUINAS, SALA DE BOMBA, LOJA DE TINTAS, QUARTO COM AR CONDICIONADO, SALA DE LEME, SALA DE HIDRÁULICA, 2 HOPPER (1 A BOMBORDO E 1 A ESTIBORDO), SALA DE CONVERSOR, SALA DE GERADOR, DE EMERGÊNCIA E PONTE. O NAVIO É EQUIPADO COM UM ALOJAMENTO PARA 13 PESSOAS. DRAGA AVALIADA EM 5.000.000,00 DIMENSÕES: COMPRIMENTO SOBRE TUDO: 77,15 M COMPRIMENTO PERPENDICULARES: 71,80 M BOCA MOLDADA: 15,00 M PROFUNDIDADE MEIA NAU MOLDADO: 5,70 M PROJECTO DE VERÃO: 4,45 M DRAGA PROJECTO: 6,10 M ALTURA: 28,85 M TONELAGEM (T): TONELAGEM BRUTA: 2472 TONELAGEM LIQUIDA: 741 PESO MORTO: 3341 MT CAPACIDADE HOPPER (TOPO DA BRAÇOLA): 2.800 M3 TUBO DE SUCÇÃO EM MOVIMENTO: 1 COM 800 MILÍMETROS DE DIÂMETRO TUBO DE DESCARGA PARA HOPER: 800 MILÍMETROS DE DIÂMETRO TUBO DE DESCARGA PARA TERRA: 600 MILÍMETROS DE DIÂMETRO PROFUNDIDADE DE DRAGAGEM: 30M VELOCIDADE MÁXIMA: 10,3 NÓS TOTAL DE ENERGIA A DIESEL INSTALADOS: 2.529 KW MOTORES PRICIPAIS: 2 MOTORES DIESEL DE 12 CILINDROS, MITSUBISHI, TIPO S12RMPTK, CADA UM DE 940 KW NOMINAL DE 1,600 RPM, DIRIGINDO UMA HÉLICE DE PASSO FIXO ATRAVÉS DE UMA CAIXA REDUTORA MASON. MOTORES AUXILIARES: 3 MOTORES DIESEL DE 6 CILINDROS, JOHN DEERE, TIPO 6090AFM85, DE 192KW NOMINAL DE 1,500 RPM, DE UNICA DIREÇÃO. MOTOR DE EMERGÊNCIA: 1 MOTOR DIESEL DE 6 CILINDROS, MITSUBISHI,TIPO 6D16T DE 106 KW NOMINAL DE 1500 RPM, DE UNICA DIREÇÃO. HÉLICES: 2 HÉLICES DE 5 PÁS DE BRONZE DE PASSO E BICOS FIXOS. MOTOR PROA: 1 MOTOR DIESEL, MITSUBSHI, HÉLICE DE PASSO FIXO CONDUZIDO EM TÚNEL DE 360KW. BOMBA DE DRAGAGEM: 1 BOMBA PARA DRAGAGEM VOSTA, TIPO VL 750, IMPULSIONADA POR UM MOTOR A DIESEL DE 870 KW MITSUBISHI, VIA CAIXA DE REDUÇÃO STORK. BOMBA DE MOVIMENTO: 1 BOMBA DE MOVIMENTO VOSTA, TIPO VL 750, IMPULSIONADA POR UM MOTOR A DIESEL DE 870 KW MITSUBISHI, VIA CAIXA DE REDUÇÃO STORK. BOMBAS DE JATO DE ÁGUA: 1 BOMBA GIW DE 2300 M3/H, DE 8 BAR, IMPULSIONADA POR UM MOTOR DIESEL, MITSHUBISHI DE 634 KW, COM REDUÇÃO VIA CAIXA MASON. CAPACIDADE DOS TANQUES DE: ÓLEO COMBUSTÍVEL: 219,0 M3 ÓLEOS LUBRIFICANTES: 13,0 M3 ÁGUA DOCE: 91,0 M3 GUINDASTES: 2 GRUAS HIDRÁULICAS PALFINGER, TIPO SWM, DE 7 TON ATÉ 10M. ACOMODAÇÕES: AS ACOMODAÇÕES CONSISTEM DE 5 DECKS. MEIOS DE SALVAÇÃO: 2 BOTES SALVA-VIDAS PARA CADA 16 PESSOAS, 1 BARCO MOB COM MOTOR DE POPA DE 25 HP.'
A12: =B12&" - "&COUNTIF($B$3:B12,B12) -> NEA TANKS - 1 | B12: NEA TANKS | C12: 240003252912 | D12: E-24/0052-NEA | H12: =EDATE(I12,-1) -> 45666 | I12: =EDATE(LEFT(L12,10),-1) -> 45697 | J12: CONTRATO Nº Nº BPCRC-014-2022-PRD | K12: DIVERSOS EQUIPAMENTOS CONFORME DI | L12: 45725 | M12: 45349 | N12: 45350 | O12: PORTO DE SANTOS - SP | P12: 10567976000102 | R12: 202400227845285 | T12: 29/11/2024 - Juntada efetuada 27/11/2024 - Docs recebidos 27/11/2024 - Cobrado novamente 18/10/2024 - Cobrado procedimento a ser adotado 09/10/2024 - Juntada efetuada 04/10/2024 - Docs recebidos 14/08/2024 - Cobrado procedimento a ser adotado 15/04/2024 - Processo incluído no controle | U12: AÉREO | V12: ="'"&SUBSTITUTE(T12,CHAR(10),"' + CHAR(13) + CHAR(10) + "&CHAR(10)&"'")&"'" -> '29/11/2024 - Juntada efetuada' + CHAR(13) + CHAR(10) + '27/11/2024 - Docs recebidos' + CHAR(13) + CHAR(10) + '27/11/2024 - Cobrado novamente' + CHAR(13) + CHAR(10) + '18/10/2024 - Cobrado procedimento a ser adotado' + CHAR(13) + CHAR(10) + '09/10/2024 - Juntada efetuada' + CHAR(13) + CHAR(10) + '04/10/2024 - Docs recebidos' + CHAR(13) + CHAR(10) + '14/08/2024 - Cobrado procedimento a ser adotado' + CHAR(13) + CHAR(10) + '15/04/2024 - Processo incluído no controle' | W12: WHEN 10 THEN '29/11/2024 - Juntada efetuada' + CHAR(13) + CHAR(10) + '27/11/2024 - Docs recebidos' + CHAR(13) + CHAR(10) + '27/11/2024 - Cobrado novamente' + CHAR(13) + CHAR(10) + '18/10/2024 - Cobrado procedimento a ser adotado' + CHAR(13) + CHAR(10) + '09/10/2024 - Juntada efetuada' + CHAR(13) + CHAR(10) + '04/10/2024 - Docs recebidos' + CHAR(13) + CHAR(10) + '14/08/2024 - Cobrado procedimento a ser adotado' + CHAR(13) + CHAR(10) + '15/04/2024 - Processo incluído no controle' | X12: WHEN 10 THEN 'DIVERSOS EQUIPAMENTOS CONFORME DI'
A13: =B13&" - "&COUNTIF($B$3:B13,B13) -> NEA TANKS - 2 | B13: NEA TANKS | C13: 240000198208 | D13: E-24/0004-NEA | H13: =EDATE(I13,-1) -> 45666 | I13: =EDATE(LEFT(L13,10),-1) -> 45697 | J13: CONTRATO Nº BPCRC-014-2022-PRD | K13: DIVERSOS EQUIPAMENTOS CONFORME DUE | L13: 45725 | M13: 45296 | N13: 45303 | O13: PORTO DE SANTOS - SP | P13: 10567976000102 | R13: 202400222101024 | T13: 29/11/2024 - Juntada efetuada 27/11/2024 - Cobrado novamente, docs recebidos 18/10/2024 - Cobrado procedimento a ser adotado 09/10/2024 - Juntada efetuada 04/10/2024 - Docs recebidos 14/08/2024 - Cobrado procedimento a ser adotado 16/02/2024 - Processo incluido no controle | U13: AÉREO | V13: ="'"&SUBSTITUTE(T13,CHAR(10),"' + CHAR(13) + CHAR(10) + "&CHAR(10)&"'")&"'" -> '29/11/2024 - Juntada efetuada' + CHAR(13) + CHAR(10) + '27/11/2024 - Cobrado novamente, docs recebidos' + CHAR(13) + CHAR(10) + '18/10/2024 - Cobrado procedimento a ser adotado' + CHAR(13) + CHAR(10) + '09/10/2024 - Juntada efetuada' + CHAR(13) + CHAR(10) + '04/10/2024 - Docs recebidos' + CHAR(13) + CHAR(10) + '14/08/2024 - Cobrado procedimento a ser adotado' + CHAR(13) + CHAR(10) + '16/02/2024 - Processo incluido no controle' | W13: WHEN 11 THEN '29/11/2024 - Juntada efetuada' + CHAR(13) + CHAR(10) + '27/11/2024 - Cobrado novamente, docs recebidos' + CHAR(13) + CHAR(10) + '18/10/2024 - Cobrado procedimento a ser adotado' + CHAR(13) + CHAR(10) + '09/10/2024 - Juntada efetuada' + CHAR(13) + CHAR(10) + '04/10/2024 - Docs recebidos' + CHAR(13) + CHAR(10) + '14/08/2024 - Cobrado procedimento a ser adotado' + CHAR(13) + CHAR(10) + '16/02/2024 - Processo incluido no controle' | X13: WHEN 11 THEN 'DIVERSOS EQUIPAMENTOS CONFORME DUE'
A14: =B14&" - "&COUNTIF($B$3:B14,B14) -> MAMMOET - 6 | B14: MAMMOET | C14: 2105759393 | D14: I-21/0343-MBG | E14: EXP-MUSA-12521 | F14: PAGA | G14: 132105065072039 | H14: =EDATE(I14,-1) -> 45683 | I14: =EDATE(LEFT(L14,10),-1) -> 45714 | J14: CONTRATO DE LOCAÇÃO S/NR DATADO DE 16/03/2021 | K14: Conjunto de Trilha Estreita usado para Guindaste Terex Demag CC 2800 - 1 com todas as peças e acessórios para montagem e operação, marca: Terex Demag, modelo: CC 2800-1, sem número de serie, ano de fabricação 2006. Uma seçao de Jib/lança de 12 metros usada para guindaste Terex-Demag CC 2800-1 com todas as peças e acessórios para montagem e operação, marca: Terex Demag, modelo: CC 2800-1, sem numero de série, ano de fabricação 2006.0 | L14: 45742 | M14: 44279 | N14: 44281 | O14: MULTIRIO-RJ | P14: 11426377000638 | R14: 202100103816828 | S14: 46105 | T14: 26/12/2024 - Juntada efetuada 23/12/2024 - Docs recebidos 29/11/2024 - Numerario enviado, ag retorno 28/11/2024 - Solicitado prorrogaçao por mais 3 mese 27/11/2024 - Cobrado procedimento a ser adotado 26/11/2024 - Juntada efetuada 22/11/2024 - Docs recebidos 14/11/2024 - Numerario enviado, ag retorno 12/11/2024 - Solicitado prorrogaçao por mais 1 mes 30/09/2024 - Cobrado procedimento a ser adotado 26/06/2024 - Juntada efetuada 26/06/2024 - Docs recebidos 14/06/2024 - Enviado Numerario, ag retorno 13/06/2024 - Solicitado prorrogação por mais 5 meses 03/06/2024 - Cobrado novamente 30/04/2024 - Cobrado procedimento a ser adotado 26/04/2024 - Juntada efetuada 19/04/2024 - Docs recebidos 05/04/2024 - Numerario e RPR enviados, ag retorno 04/04/2024 - Informado que será prorrogado por mais 2 meses 28/02/2024 - Cobrado procedimento a ser adotado 25/10/2023 - Juntada efetuada 23/10/2023 - Docs recebidos 06/10/2023 - RPR, TR e Numerario enviados, ag retorno 03/10/2023 - Solicitado prorrogação por mais 6 meses 30/08/2023 - Cobrado procedimento a ser adotado 25/07/2023 - Juntada efetuada atraves do DOSSIE 21/07/2023 - Docs recebidos 27/06/2023 - Enviado Numerario, TR e RPR, ag retorno 22/06/2023 - Solicitado renovação por 3 meses 01/06/2023 - Cobrado procedimento a ser adotado 23/03/2023 - Juntada efetuada através do DOSSIE 20/03/2023 - Recebido documentação 28/02/2023 - Cobrado novamente 31/01/2023 - Cobrado procedimento a ser adotado 25/03/2022 - Juntada anexada através do DOSSIE 17/02/2022 - Solicitado prorrogação por 12 meses, TR, RAT e Numerário enviados, aguardando retorno 27/01/2022 - Cobrado procedimento a ser adotado 24/09/2021 - Recebido documentos, juntada efetuada pelo DOSSIE 20/09/2021 - Cobrado novamente 27/08/2021 - Cobrado novamente, solicitado prorrogação por 6 meses, TR e Numerario enviados, aguardando retorno 27/07/2021 - Cobrado procedimento a ser adotado 11/05/2021 - Processo incluído no controle | U14: MARÍTIMO | V14: ="'"&SUBSTITUTE(T14,CHAR(10),"' + CHAR(13) + CHAR(10) + "&CHAR(10)&"'")&"'" -> '26/12/2024 - Juntada efetuada' + CHAR(13) + CHAR(10) + '23/12/2024 - Docs recebidos' + CHAR(13) + CHAR(10) + '29/11/2024 - Numerario enviado, ag retorno' + CHAR(13) + CHAR(10) + '28/11/2024 - Solicitado prorrogaçao por mais 3 mese' + CHAR(13) + CHAR(10) + '27/11/2024 - Cobrado procedimento a ser adotado' + CHAR(13) + CHAR(10) + '26/11/2024 - Juntada efetuada' + CHAR(13) + CHAR(10) + '22/11/2024 - Docs recebidos' + CHAR(13) + CHAR(10) + '14/11/2024 - Numerario enviado, ag retorno' + CHAR(13) + CHAR(10) + '12/11/2024 - Solicitado prorrogaçao por mais 1 mes' + CHAR(13) + CHAR(10) + '30/09/2024 - Cobrado procedimento a ser adotado' + CHAR(13) + CHAR(10) + '26/06/2024 - Juntada efetuada' + CHAR(13) + CHAR(10) + '26/06/2024 - Docs recebidos' + CHAR(13) + CHAR(10) + '14/06/2024 - Enviado Numerario, ag retorno' + CHAR(13) + CHAR(10) + '13/06/2024 - Solicitado prorrogação por mais 5 meses' + CHAR(13) + CHAR(10) + '03/06/2024 - Cobrado novamente' + CHAR(13) + CHAR(10) + '30/04/2024 - Cobrado procedimento a ser adotado' + CHAR(13) + CHAR(10) + '26/04/2024 - Juntada efetuada' + CHAR(13) + CHAR(10) + '19/04/2024 - Docs recebidos' + CHAR(13) + CHAR(10) + '05/04/2024 - Numerario e RPR enviados, ag retorno' + CHAR(13) + CHAR(10) + '04/04/2024 - Informado que será prorrogado por mais 2 meses' + CHAR(13) + CHAR(10) + '28/02/2024 - Cobrado procedimento a ser adotado' + CHAR(13) + CHAR(10) + '25/10/2023 - Juntada efetuada' + CHAR(13) + CHAR(10) + '23/10/2023 - Docs recebidos' + CHAR(13) + CHAR(10) + '06/10/2023 - RPR, TR e Numerario enviados, ag retorno' + CHAR(13) + CHAR(10) + '03/10/2023 - Solicitado prorrogação por mais 6 meses' + CHAR(13) + CHAR(10) + '30/08/2023 - Cobrado procedimento a ser adotado' + CHAR(13) + CHAR(10) + '25/07/2023 - Juntada efetuada atraves do DOSSIE' + CHAR(13) + CHAR(10) + '21/07/2023 - Docs recebidos' + CHAR(13) + CHAR(10) + '27/06/2023 - Enviado Numerario, TR e RPR, ag retorno' + CHAR(13) + CHAR(10) + '22/06/2023 - Solicitado renovação por 3 meses' + CHAR(13) + CHAR(10) + '01/06/2023 - Cobrado procedimento a ser adotado' + CHAR(13) + CHAR(10) + '23/03/2023 - Juntada efetuada através do DOSSIE' + CHAR(13) + CHAR(10) + '20/03/2023 - Recebido documentação' + CHAR(13) + CHAR(10) + '28/02/2023 - Cobrado novamente' + CHAR(13) + CHAR(10) + '31/01/2023 - Cobrado procedimento a ser adotado' + CHAR(13) + CHAR(10) + '25/03/2022 - Juntada anexada através do DOSSIE' + CHAR(13) + CHAR(10) + '17/02/2022 - Solicitado prorrogação por 12 meses, TR, RAT e Numerário enviados, aguardando retorno' + CHAR(13) + CHAR(10) + '27/01/2022 - Cobrado procedimento a ser adotado' + CHAR(13) + CHAR(10) + '24/09/2021 - Recebido documentos, juntada efetuada pelo DOSSIE' + CHAR(13) + CHAR(10) + '20/09/2021 - Cobrado novamente' + CHAR(13) + CHAR(10) + '27/08/2021 - Cobrado novamente, solicitado prorrogação por 6 meses, TR e Numerario enviados, aguardando retorno' + CHAR(13) + CHAR(10) + '27/07/2021 - Cobrado procedimento a ser adotado' + CHAR(13) + CHAR(10) + '11/05/2021 - Processo incluído no controle' | W14: WHEN 12 THEN '26/12/2024 - Juntada efetuada' + CHAR(13) + CHAR(10) + '23/12/2024 - Docs recebidos' + CHAR(13) + CHAR(10) + '29/11/2024 - Numerario enviado, ag retorno' + CHAR(13) + CHAR(10) + '28/11/2024 - Solicitado prorrogaçao por mais 3 mese' + CHAR(13) + CHAR(10) + '27/11/2024 - Cobrado procedimento a ser adotado' + CHAR(13) + CHAR(10) + '26/11/2024 - Juntada efetuada' + CHAR(13) + CHAR(10) + '22/11/2024 - Docs recebidos' + CHAR(13) + CHAR(10) + '14/11/2024 - Numerario enviado, ag retorno' + CHAR(13) + CHAR(10) + '12/11/2024 - Solicitado prorrogaçao por mais 1 mes' + CHAR(13) + CHAR(10) + '30/09/2024 - Cobrado procedimento a ser adotado' + CHAR(13) + CHAR(10) + '26/06/2024 - Juntada efetuada' + CHAR(13) + CHAR(10) + '26/06/2024 - Docs recebidos' + CHAR(13) + CHAR(10) + '14/06/2024 - Enviado Numerario, ag retorno' + CHAR(13) + CHAR(10) + '13/06/2024 - Solicitado prorrogação por mais 5 meses' + CHAR(13) + CHAR(10) + '03/06/2024 - Cobrado novamente' + CHAR(13) + CHAR(10) + '30/04/2024 - Cobrado procedimento a ser adotado' + CHAR(13) + CHAR(10) + '26/04/2024 - Juntada efetuada' + CHAR(13) + CHAR(10) + '19/04/2024 - Docs recebidos' + CHAR(13) + CHAR(10) + '05/04/2024 - Numerario e RPR enviados, ag retorno' + CHAR(13) + CHAR(10) + '04/04/2024 - Informado que será prorrogado por mais 2 meses' + CHAR(13) + CHAR(10) + '28/02/2024 - Cobrado procedimento a ser adotado' + CHAR(13) + CHAR(10) + '25/10/2023 - Juntada efetuada' + CHAR(13) + CHAR(10) + '23/10/2023 - Docs recebidos' + CHAR(13) + CHAR(10) + '06/10/2023 - RPR, TR e Numerario enviados, ag retorno' + CHAR(13) + CHAR(10) + '03/10/2023 - Solicitado prorrogação por mais 6 meses' + CHAR(13) + CHAR(10) + '30/08/2023 - Cobrado procedimento a ser adotado' + CHAR(13) + CHAR(10) + '25/07/2023 - Juntada efetuada atraves do DOSSIE' + CHAR(13) + CHAR(10) + '21/07/2023 - Docs recebidos' + CHAR(13) + CHAR(10) + '27/06/2023 - Enviado Numerario, TR e RPR, ag retorno' + CHAR(13) + CHAR(10) + '22/06/2023 - Solicitado renovação por 3 meses' + CHAR(13) + CHAR(10) + '01/06/2023 - Cobrado procedimento a ser adotado' + CHAR(13) + CHAR(10) + '23/03/2023 - Juntada efetuada através do DOSSIE' + CHAR(13) + CHAR(10) + '20/03/2023 - Recebido documentação' + CHAR(13) + CHAR(10) + '28/02/2023 - Cobrado novamente' + CHAR(13) + CHAR(10) + '31/01/2023 - Cobrado procedimento a ser adotado' + CHAR(13) + CHAR(10) + '25/03/2022 - Juntada anexada através do DOSSIE' + CHAR(13) + CHAR(10) + '17/02/2022 - Solicitado prorrogação por 12 meses, TR, RAT e Numerário enviados, aguardando retorno' + CHAR(13) + CHAR(10) + '27/01/2022 - Cobrado procedimento a ser adotado' + CHAR(13) + CHAR(10) + '24/09/2021 - Recebido documentos, juntada efetuada pelo DOSSIE' + CHAR(13) + CHAR(10) + '20/09/2021 - Cobrado novamente' + CHAR(13) + CHAR(10) + '27/08/2021 - Cobrado novamente, solicitado prorrogação por 6 meses, TR e Numerario enviados, aguardando retorno' + CHAR(13) + CHAR(10) + '27/07/2021 - Cobrado procedimento a ser adotado' + CHAR(13) + CHAR(10) + '11/05/2021 - Processo incluído no controle' | X14: WHEN 12 THEN 'CONJUNTO DE TRILHA ESTREITA USADO PARA GUINDASTE TEREX DEMAG CC 2800 - 1 COM TODAS AS PEÇAS E ACESSÓRIOS PARA MONTAGEM E OPERAÇÃO, MARCA: TEREX DEMAG, MODELO: CC 2800-1, SEM NÚMERO DE SERIE, ANO DE FABRICAÇÃO 2006. UMA SEÇAO DE JIB/LANÇA DE 12 METROS USADA PARA GUINDASTE TEREX-DEMAG CC 2800-1 COM TODAS AS PEÇAS E ACESSÓRIOS PARA MONTAGEM E OPERAÇÃO, MARCA: TEREX DEMAG, MODELO: CC 2800-1, SEM NUMERO DE SÉRIE, ANO DE FABRICAÇÃO 2006.0'
